[2022-05-31 18:07:57,306] {taskinstance.py:1160} INFO - Dependencies all met for <TaskInstance: yellow_taxi_ingestion_gcs_dag.local_to_gcs_task scheduled__2022-02-01T06:00:00+00:00 [queued]>
[2022-05-31 18:07:57,322] {taskinstance.py:1160} INFO - Dependencies all met for <TaskInstance: yellow_taxi_ingestion_gcs_dag.local_to_gcs_task scheduled__2022-02-01T06:00:00+00:00 [queued]>
[2022-05-31 18:07:57,324] {taskinstance.py:1357} INFO - 
--------------------------------------------------------------------------------
[2022-05-31 18:07:57,326] {taskinstance.py:1358} INFO - Starting attempt 1 of 1
[2022-05-31 18:07:57,328] {taskinstance.py:1359} INFO - 
--------------------------------------------------------------------------------
[2022-05-31 18:07:57,349] {taskinstance.py:1378} INFO - Executing <Task(PythonOperator): local_to_gcs_task> on 2022-02-01 06:00:00+00:00
[2022-05-31 18:07:57,358] {standard_task_runner.py:52} INFO - Started process 1047 to run task
[2022-05-31 18:07:57,363] {standard_task_runner.py:79} INFO - Running: ['***', 'tasks', 'run', 'yellow_taxi_ingestion_gcs_dag', 'local_to_gcs_task', 'scheduled__2022-02-01T06:00:00+00:00', '--job-id', '323', '--raw', '--subdir', 'DAGS_FOLDER/yellow_taxi_ingestion.py', '--cfg-path', '/tmp/tmps7crxv38', '--error-file', '/tmp/tmpaimgmcvr']
[2022-05-31 18:07:57,366] {standard_task_runner.py:80} INFO - Job 323: Subtask local_to_gcs_task
[2022-05-31 18:07:57,435] {task_command.py:370} INFO - Running <TaskInstance: yellow_taxi_ingestion_gcs_dag.local_to_gcs_task scheduled__2022-02-01T06:00:00+00:00 [running]> on host 8ac972de2f4f
[2022-05-31 18:07:57,475] {warnings.py:110} WARNING - /home/***/.local/lib/python3.7/site-packages/***/utils/context.py:202: AirflowContextDeprecationWarning: Accessing 'execution_date' from the template is deprecated and will be removed in a future version. Please use 'data_interval_start' or 'logical_date' instead.
  warnings.warn(_create_deprecation_warning(key, self._deprecation_replacements[key]))

[2022-05-31 18:07:57,525] {taskinstance.py:1572} INFO - Exporting the following env vars:
AIRFLOW_CTX_DAG_OWNER=***
AIRFLOW_CTX_DAG_ID=yellow_taxi_ingestion_gcs_dag
AIRFLOW_CTX_TASK_ID=local_to_gcs_task
AIRFLOW_CTX_EXECUTION_DATE=2022-02-01T06:00:00+00:00
AIRFLOW_CTX_TRY_NUMBER=1
AIRFLOW_CTX_DAG_RUN_ID=scheduled__2022-02-01T06:00:00+00:00
[2022-05-31 18:07:57,529] {taskinstance.py:1890} ERROR - Task failed with exception
Traceback (most recent call last):
  File "/home/airflow/.local/lib/python3.7/site-packages/airflow/operators/python.py", line 171, in execute
    return_value = self.execute_callable()
  File "/home/airflow/.local/lib/python3.7/site-packages/airflow/operators/python.py", line 189, in execute_callable
    return self.python_callable(*self.op_args, **self.op_kwargs)
  File "/opt/airflow/dags/yellow_taxi_ingestion.py", line 46, in upload_to_gcs
    client = storage.Client()
  File "/home/airflow/.local/lib/python3.7/site-packages/google/cloud/storage/client.py", line 128, in __init__
    _http=_http,
  File "/home/airflow/.local/lib/python3.7/site-packages/google/cloud/client/__init__.py", line 320, in __init__
    _ClientProjectMixin.__init__(self, project=project, credentials=credentials)
  File "/home/airflow/.local/lib/python3.7/site-packages/google/cloud/client/__init__.py", line 268, in __init__
    project = self._determine_default(project)
  File "/home/airflow/.local/lib/python3.7/site-packages/google/cloud/client/__init__.py", line 287, in _determine_default
    return _determine_default_project(project)
  File "/home/airflow/.local/lib/python3.7/site-packages/google/cloud/_helpers/__init__.py", line 152, in _determine_default_project
    _, project = google.auth.default()
  File "/home/airflow/.local/lib/python3.7/site-packages/google/auth/_default.py", line 546, in default
    credentials, project_id = checker()
  File "/home/airflow/.local/lib/python3.7/site-packages/google/auth/_default.py", line 539, in <lambda>
    lambda: _get_explicit_environ_credentials(quota_project_id=quota_project_id),
  File "/home/airflow/.local/lib/python3.7/site-packages/google/auth/_default.py", line 219, in _get_explicit_environ_credentials
    os.environ[environment_vars.CREDENTIALS], quota_project_id=quota_project_id
  File "/home/airflow/.local/lib/python3.7/site-packages/google/auth/_default.py", line 118, in load_credentials_from_file
    "File {} was not found.".format(filename)
google.auth.exceptions.DefaultCredentialsError: File ~/google/credentials/google_credentials.json was not found.
[2022-05-31 18:07:57,549] {taskinstance.py:1401} INFO - Marking task as FAILED. dag_id=yellow_taxi_ingestion_gcs_dag, task_id=local_to_gcs_task, execution_date=20220201T060000, start_date=20220531T180757, end_date=20220531T180757
[2022-05-31 18:07:57,563] {standard_task_runner.py:97} ERROR - Failed to execute job 323 for task local_to_gcs_task (File ~/google/credentials/google_credentials.json was not found.; 1047)
[2022-05-31 18:07:57,577] {local_task_job.py:156} INFO - Task exited with return code 1
[2022-05-31 18:07:57,632] {local_task_job.py:273} INFO - 0 downstream tasks scheduled from follow-on schedule check
[2022-05-31 18:50:02,692] {taskinstance.py:1160} INFO - Dependencies all met for <TaskInstance: yellow_taxi_ingestion_gcs_dag.local_to_gcs_task scheduled__2022-02-01T06:00:00+00:00 [queued]>
[2022-05-31 18:50:02,707] {taskinstance.py:1160} INFO - Dependencies all met for <TaskInstance: yellow_taxi_ingestion_gcs_dag.local_to_gcs_task scheduled__2022-02-01T06:00:00+00:00 [queued]>
[2022-05-31 18:50:02,711] {taskinstance.py:1357} INFO - 
--------------------------------------------------------------------------------
[2022-05-31 18:50:02,717] {taskinstance.py:1358} INFO - Starting attempt 1 of 1
[2022-05-31 18:50:02,721] {taskinstance.py:1359} INFO - 
--------------------------------------------------------------------------------
[2022-05-31 18:50:02,741] {taskinstance.py:1378} INFO - Executing <Task(PythonOperator): local_to_gcs_task> on 2022-02-01 06:00:00+00:00
[2022-05-31 18:50:02,753] {standard_task_runner.py:52} INFO - Started process 1196 to run task
[2022-05-31 18:50:02,758] {standard_task_runner.py:79} INFO - Running: ['***', 'tasks', 'run', 'yellow_taxi_ingestion_gcs_dag', 'local_to_gcs_task', 'scheduled__2022-02-01T06:00:00+00:00', '--job-id', '417', '--raw', '--subdir', 'DAGS_FOLDER/yellow_taxi_ingestion.py', '--cfg-path', '/tmp/tmpb14rzfos', '--error-file', '/tmp/tmpnwmsny0j']
[2022-05-31 18:50:02,767] {standard_task_runner.py:80} INFO - Job 417: Subtask local_to_gcs_task
[2022-05-31 18:50:02,844] {task_command.py:370} INFO - Running <TaskInstance: yellow_taxi_ingestion_gcs_dag.local_to_gcs_task scheduled__2022-02-01T06:00:00+00:00 [running]> on host 3f188d455d5a
[2022-05-31 18:50:02,884] {warnings.py:110} WARNING - /home/***/.local/lib/python3.7/site-packages/***/utils/context.py:202: AirflowContextDeprecationWarning: Accessing 'execution_date' from the template is deprecated and will be removed in a future version. Please use 'data_interval_start' or 'logical_date' instead.
  warnings.warn(_create_deprecation_warning(key, self._deprecation_replacements[key]))

[2022-05-31 18:50:02,922] {taskinstance.py:1572} INFO - Exporting the following env vars:
AIRFLOW_CTX_DAG_OWNER=***
AIRFLOW_CTX_DAG_ID=yellow_taxi_ingestion_gcs_dag
AIRFLOW_CTX_TASK_ID=local_to_gcs_task
AIRFLOW_CTX_EXECUTION_DATE=2022-02-01T06:00:00+00:00
AIRFLOW_CTX_TRY_NUMBER=1
AIRFLOW_CTX_DAG_RUN_ID=scheduled__2022-02-01T06:00:00+00:00
[2022-05-31 18:50:08,065] {python.py:173} INFO - Done. Returned value was: None
[2022-05-31 18:50:08,108] {taskinstance.py:1401} INFO - Marking task as SUCCESS. dag_id=yellow_taxi_ingestion_gcs_dag, task_id=local_to_gcs_task, execution_date=20220201T060000, start_date=20220531T185002, end_date=20220531T185008
[2022-05-31 18:50:08,192] {local_task_job.py:156} INFO - Task exited with return code 0
[2022-05-31 18:50:08,228] {local_task_job.py:273} INFO - 0 downstream tasks scheduled from follow-on schedule check
