[2022-05-30 22:10:00,699] {taskinstance.py:1160} INFO - Dependencies all met for <TaskInstance: LocalIngestionDag.ingest scheduled__2022-02-02T06:00:00+00:00 [queued]>
[2022-05-30 22:10:00,707] {taskinstance.py:1160} INFO - Dependencies all met for <TaskInstance: LocalIngestionDag.ingest scheduled__2022-02-02T06:00:00+00:00 [queued]>
[2022-05-30 22:10:00,708] {taskinstance.py:1357} INFO - 
--------------------------------------------------------------------------------
[2022-05-30 22:10:00,709] {taskinstance.py:1358} INFO - Starting attempt 3 of 3
[2022-05-30 22:10:00,710] {taskinstance.py:1359} INFO - 
--------------------------------------------------------------------------------
[2022-05-30 22:10:00,723] {taskinstance.py:1378} INFO - Executing <Task(PythonOperator): ingest> on 2022-02-02 06:00:00+00:00
[2022-05-30 22:10:00,734] {standard_task_runner.py:52} INFO - Started process 823 to run task
[2022-05-30 22:10:00,737] {standard_task_runner.py:79} INFO - Running: ['***', 'tasks', 'run', 'LocalIngestionDag', 'ingest', 'scheduled__2022-02-02T06:00:00+00:00', '--job-id', '182', '--raw', '--subdir', 'DAGS_FOLDER/data_ingestion_local.py', '--cfg-path', '/tmp/tmprulw55ld', '--error-file', '/tmp/tmpqx2v7ug3']
[2022-05-30 22:10:00,738] {standard_task_runner.py:80} INFO - Job 182: Subtask ingest
[2022-05-30 22:10:00,787] {task_command.py:370} INFO - Running <TaskInstance: LocalIngestionDag.ingest scheduled__2022-02-02T06:00:00+00:00 [running]> on host 8ac972de2f4f
[2022-05-30 22:10:00,816] {warnings.py:110} WARNING - /home/***/.local/lib/python3.7/site-packages/***/utils/context.py:202: AirflowContextDeprecationWarning: Accessing 'execution_date' from the template is deprecated and will be removed in a future version. Please use 'data_interval_start' or 'logical_date' instead.
  warnings.warn(_create_deprecation_warning(key, self._deprecation_replacements[key]))

[2022-05-30 22:10:00,843] {taskinstance.py:1572} INFO - Exporting the following env vars:
AIRFLOW_CTX_DAG_OWNER=***
AIRFLOW_CTX_DAG_ID=LocalIngestionDag
AIRFLOW_CTX_TASK_ID=ingest
AIRFLOW_CTX_EXECUTION_DATE=2022-02-02T06:00:00+00:00
AIRFLOW_CTX_TRY_NUMBER=3
AIRFLOW_CTX_DAG_RUN_ID=scheduled__2022-02-02T06:00:00+00:00
[2022-05-30 22:10:00,844] {logging_mixin.py:115} INFO - yellow_taxi_2022_02 /opt/***/output_2022-02.parquet 2022-02-02T06:00:00+00:00
[2022-05-30 22:10:00,947] {logging_mixin.py:115} INFO - connection established successfully, inserting data...
[2022-05-30 22:10:01,001] {taskinstance.py:1890} ERROR - Task failed with exception
Traceback (most recent call last):
  File "/home/airflow/.local/lib/python3.7/site-packages/airflow/operators/python.py", line 171, in execute
    return_value = self.execute_callable()
  File "/home/airflow/.local/lib/python3.7/site-packages/airflow/operators/python.py", line 189, in execute_callable
    return self.python_callable(*self.op_args, **self.op_kwargs)
  File "/opt/airflow/dags/ingest_script.py", line 18, in ingest_callable
    df_iter = pd.read_parquet(parquet_file)
  File "/home/airflow/.local/lib/python3.7/site-packages/pandas/io/parquet.py", line 500, in read_parquet
    **kwargs,
  File "/home/airflow/.local/lib/python3.7/site-packages/pandas/io/parquet.py", line 236, in read
    mode="rb",
  File "/home/airflow/.local/lib/python3.7/site-packages/pandas/io/parquet.py", line 102, in _get_path_or_handle
    path_or_handle, mode, is_text=False, storage_options=storage_options
  File "/home/airflow/.local/lib/python3.7/site-packages/pandas/io/common.py", line 711, in get_handle
    handle = open(handle, ioargs.mode)
FileNotFoundError: [Errno 2] No such file or directory: '/opt/airflow/output_2022-02.parquet'
[2022-05-30 22:10:01,011] {taskinstance.py:1401} INFO - Marking task as FAILED. dag_id=LocalIngestionDag, task_id=ingest, execution_date=20220202T060000, start_date=20220530T221000, end_date=20220530T221001
[2022-05-30 22:10:01,022] {standard_task_runner.py:97} ERROR - Failed to execute job 182 for task ingest ([Errno 2] No such file or directory: '/opt/airflow/output_2022-02.parquet'; 823)
[2022-05-30 22:10:01,072] {local_task_job.py:156} INFO - Task exited with return code 1
[2022-05-30 22:10:01,101] {local_task_job.py:273} INFO - 0 downstream tasks scheduled from follow-on schedule check
[2022-05-30 22:47:02,868] {taskinstance.py:1160} INFO - Dependencies all met for <TaskInstance: LocalIngestionDag.ingest scheduled__2022-02-02T06:00:00+00:00 [queued]>
[2022-05-30 22:47:02,879] {taskinstance.py:1160} INFO - Dependencies all met for <TaskInstance: LocalIngestionDag.ingest scheduled__2022-02-02T06:00:00+00:00 [queued]>
[2022-05-30 22:47:02,881] {taskinstance.py:1357} INFO - 
--------------------------------------------------------------------------------
[2022-05-30 22:47:02,882] {taskinstance.py:1358} INFO - Starting attempt 3 of 3
[2022-05-30 22:47:02,882] {taskinstance.py:1359} INFO - 
--------------------------------------------------------------------------------
[2022-05-30 22:47:02,897] {taskinstance.py:1378} INFO - Executing <Task(PythonOperator): ingest> on 2022-02-02 06:00:00+00:00
[2022-05-30 22:47:02,904] {standard_task_runner.py:52} INFO - Started process 3221 to run task
[2022-05-30 22:47:02,908] {standard_task_runner.py:79} INFO - Running: ['***', 'tasks', 'run', 'LocalIngestionDag', 'ingest', 'scheduled__2022-02-02T06:00:00+00:00', '--job-id', '273', '--raw', '--subdir', 'DAGS_FOLDER/data_ingestion_local.py', '--cfg-path', '/tmp/tmpfqk8rx2c', '--error-file', '/tmp/tmpa212qx_i']
[2022-05-30 22:47:02,910] {standard_task_runner.py:80} INFO - Job 273: Subtask ingest
[2022-05-30 22:47:02,971] {task_command.py:370} INFO - Running <TaskInstance: LocalIngestionDag.ingest scheduled__2022-02-02T06:00:00+00:00 [running]> on host 8ac972de2f4f
[2022-05-30 22:47:03,005] {warnings.py:110} WARNING - /home/***/.local/lib/python3.7/site-packages/***/utils/context.py:202: AirflowContextDeprecationWarning: Accessing 'execution_date' from the template is deprecated and will be removed in a future version. Please use 'data_interval_start' or 'logical_date' instead.
  warnings.warn(_create_deprecation_warning(key, self._deprecation_replacements[key]))

[2022-05-30 22:47:03,038] {taskinstance.py:1572} INFO - Exporting the following env vars:
AIRFLOW_CTX_DAG_OWNER=***
AIRFLOW_CTX_DAG_ID=LocalIngestionDag
AIRFLOW_CTX_TASK_ID=ingest
AIRFLOW_CTX_EXECUTION_DATE=2022-02-02T06:00:00+00:00
AIRFLOW_CTX_TRY_NUMBER=3
AIRFLOW_CTX_DAG_RUN_ID=scheduled__2022-02-02T06:00:00+00:00
[2022-05-30 22:47:03,041] {logging_mixin.py:115} INFO - yellow_taxi_2022_02 /opt/***/output_2022-02.parquet 2022-02-02T06:00:00+00:00
[2022-05-30 22:47:03,076] {logging_mixin.py:115} INFO - connection established successfully, inserting data...
[2022-05-30 22:47:23,712] {local_task_job.py:156} INFO - Task exited with return code Negsignal.SIGKILL
[2022-05-30 22:47:23,747] {taskinstance.py:1401} INFO - Marking task as FAILED. dag_id=LocalIngestionDag, task_id=ingest, execution_date=20220202T060000, start_date=20220530T224702, end_date=20220530T224723
[2022-05-30 22:47:23,782] {local_task_job.py:273} INFO - 0 downstream tasks scheduled from follow-on schedule check
[2022-05-30 22:59:23,785] {taskinstance.py:1160} INFO - Dependencies all met for <TaskInstance: LocalIngestionDag.ingest scheduled__2022-02-02T06:00:00+00:00 [queued]>
[2022-05-30 22:59:23,794] {taskinstance.py:1160} INFO - Dependencies all met for <TaskInstance: LocalIngestionDag.ingest scheduled__2022-02-02T06:00:00+00:00 [queued]>
[2022-05-30 22:59:23,795] {taskinstance.py:1357} INFO - 
--------------------------------------------------------------------------------
[2022-05-30 22:59:23,796] {taskinstance.py:1358} INFO - Starting attempt 3 of 3
[2022-05-30 22:59:23,797] {taskinstance.py:1359} INFO - 
--------------------------------------------------------------------------------
[2022-05-30 22:59:23,805] {taskinstance.py:1378} INFO - Executing <Task(PythonOperator): ingest> on 2022-02-02 06:00:00+00:00
[2022-05-30 22:59:23,811] {standard_task_runner.py:52} INFO - Started process 610 to run task
[2022-05-30 22:59:23,815] {standard_task_runner.py:79} INFO - Running: ['***', 'tasks', 'run', 'LocalIngestionDag', 'ingest', 'scheduled__2022-02-02T06:00:00+00:00', '--job-id', '16', '--raw', '--subdir', 'DAGS_FOLDER/data_ingestion_local.py', '--cfg-path', '/tmp/tmpqp64omk5', '--error-file', '/tmp/tmpadbzw1gt']
[2022-05-30 22:59:23,819] {standard_task_runner.py:80} INFO - Job 16: Subtask ingest
[2022-05-30 22:59:23,867] {task_command.py:370} INFO - Running <TaskInstance: LocalIngestionDag.ingest scheduled__2022-02-02T06:00:00+00:00 [running]> on host 973151ef250d
[2022-05-30 22:59:23,892] {warnings.py:110} WARNING - /home/***/.local/lib/python3.7/site-packages/***/utils/context.py:202: AirflowContextDeprecationWarning: Accessing 'execution_date' from the template is deprecated and will be removed in a future version. Please use 'data_interval_start' or 'logical_date' instead.
  warnings.warn(_create_deprecation_warning(key, self._deprecation_replacements[key]))

[2022-05-30 22:59:23,921] {taskinstance.py:1572} INFO - Exporting the following env vars:
AIRFLOW_CTX_DAG_OWNER=***
AIRFLOW_CTX_DAG_ID=LocalIngestionDag
AIRFLOW_CTX_TASK_ID=ingest
AIRFLOW_CTX_EXECUTION_DATE=2022-02-02T06:00:00+00:00
AIRFLOW_CTX_TRY_NUMBER=3
AIRFLOW_CTX_DAG_RUN_ID=scheduled__2022-02-02T06:00:00+00:00
[2022-05-30 22:59:23,925] {logging_mixin.py:115} INFO - yellow_taxi_2022_02 /opt/***/output_2022-02.parquet 2022-02-02T06:00:00+00:00
[2022-05-30 22:59:23,945] {taskinstance.py:1890} ERROR - Task failed with exception
Traceback (most recent call last):
  File "/home/airflow/.local/lib/python3.7/site-packages/sqlalchemy/engine/base.py", line 3141, in _wrap_pool_connect
    return fn()
  File "/home/airflow/.local/lib/python3.7/site-packages/sqlalchemy/pool/base.py", line 301, in connect
    return _ConnectionFairy._checkout(self)
  File "/home/airflow/.local/lib/python3.7/site-packages/sqlalchemy/pool/base.py", line 755, in _checkout
    fairy = _ConnectionRecord.checkout(pool)
  File "/home/airflow/.local/lib/python3.7/site-packages/sqlalchemy/pool/base.py", line 419, in checkout
    rec = pool._do_get()
  File "/home/airflow/.local/lib/python3.7/site-packages/sqlalchemy/pool/impl.py", line 145, in _do_get
    self._dec_overflow()
  File "/home/airflow/.local/lib/python3.7/site-packages/sqlalchemy/util/langhelpers.py", line 72, in __exit__
    with_traceback=exc_tb,
  File "/home/airflow/.local/lib/python3.7/site-packages/sqlalchemy/util/compat.py", line 211, in raise_
    raise exception
  File "/home/airflow/.local/lib/python3.7/site-packages/sqlalchemy/pool/impl.py", line 142, in _do_get
    return self._create_connection()
  File "/home/airflow/.local/lib/python3.7/site-packages/sqlalchemy/pool/base.py", line 247, in _create_connection
    return _ConnectionRecord(self)
  File "/home/airflow/.local/lib/python3.7/site-packages/sqlalchemy/pool/base.py", line 362, in __init__
    self.__connect(first_connect_check=True)
  File "/home/airflow/.local/lib/python3.7/site-packages/sqlalchemy/pool/base.py", line 605, in __connect
    pool.logger.debug("Error on connect(): %s", e)
  File "/home/airflow/.local/lib/python3.7/site-packages/sqlalchemy/util/langhelpers.py", line 72, in __exit__
    with_traceback=exc_tb,
  File "/home/airflow/.local/lib/python3.7/site-packages/sqlalchemy/util/compat.py", line 211, in raise_
    raise exception
  File "/home/airflow/.local/lib/python3.7/site-packages/sqlalchemy/pool/base.py", line 599, in __connect
    connection = pool._invoke_creator(self)
  File "/home/airflow/.local/lib/python3.7/site-packages/sqlalchemy/engine/create.py", line 578, in connect
    return dialect.connect(*cargs, **cparams)
  File "/home/airflow/.local/lib/python3.7/site-packages/sqlalchemy/engine/default.py", line 583, in connect
    return self.dbapi.connect(*cargs, **cparams)
  File "/home/airflow/.local/lib/python3.7/site-packages/psycopg2/__init__.py", line 122, in connect
    conn = _connect(dsn, connection_factory=connection_factory, **kwasync)
psycopg2.OperationalError: could not translate host name "pgdatabase" to address: Name or service not known


The above exception was the direct cause of the following exception:

Traceback (most recent call last):
  File "/home/airflow/.local/lib/python3.7/site-packages/airflow/operators/python.py", line 171, in execute
    return_value = self.execute_callable()
  File "/home/airflow/.local/lib/python3.7/site-packages/airflow/operators/python.py", line 189, in execute_callable
    return self.python_callable(*self.op_args, **self.op_kwargs)
  File "/opt/airflow/dags/ingest_script.py", line 13, in ingest_callable
    engine.connect()
  File "/home/airflow/.local/lib/python3.7/site-packages/sqlalchemy/engine/base.py", line 3095, in connect
    return self._connection_cls(self, close_with_result=close_with_result)
  File "/home/airflow/.local/lib/python3.7/site-packages/sqlalchemy/engine/base.py", line 91, in __init__
    else engine.raw_connection()
  File "/home/airflow/.local/lib/python3.7/site-packages/sqlalchemy/engine/base.py", line 3174, in raw_connection
    return self._wrap_pool_connect(self.pool.connect, _connection)
  File "/home/airflow/.local/lib/python3.7/site-packages/sqlalchemy/engine/base.py", line 3145, in _wrap_pool_connect
    e, dialect, self
  File "/home/airflow/.local/lib/python3.7/site-packages/sqlalchemy/engine/base.py", line 2004, in _handle_dbapi_exception_noconnection
    sqlalchemy_exception, with_traceback=exc_info[2], from_=e
  File "/home/airflow/.local/lib/python3.7/site-packages/sqlalchemy/util/compat.py", line 211, in raise_
    raise exception
  File "/home/airflow/.local/lib/python3.7/site-packages/sqlalchemy/engine/base.py", line 3141, in _wrap_pool_connect
    return fn()
  File "/home/airflow/.local/lib/python3.7/site-packages/sqlalchemy/pool/base.py", line 301, in connect
    return _ConnectionFairy._checkout(self)
  File "/home/airflow/.local/lib/python3.7/site-packages/sqlalchemy/pool/base.py", line 755, in _checkout
    fairy = _ConnectionRecord.checkout(pool)
  File "/home/airflow/.local/lib/python3.7/site-packages/sqlalchemy/pool/base.py", line 419, in checkout
    rec = pool._do_get()
  File "/home/airflow/.local/lib/python3.7/site-packages/sqlalchemy/pool/impl.py", line 145, in _do_get
    self._dec_overflow()
  File "/home/airflow/.local/lib/python3.7/site-packages/sqlalchemy/util/langhelpers.py", line 72, in __exit__
    with_traceback=exc_tb,
  File "/home/airflow/.local/lib/python3.7/site-packages/sqlalchemy/util/compat.py", line 211, in raise_
    raise exception
  File "/home/airflow/.local/lib/python3.7/site-packages/sqlalchemy/pool/impl.py", line 142, in _do_get
    return self._create_connection()
  File "/home/airflow/.local/lib/python3.7/site-packages/sqlalchemy/pool/base.py", line 247, in _create_connection
    return _ConnectionRecord(self)
  File "/home/airflow/.local/lib/python3.7/site-packages/sqlalchemy/pool/base.py", line 362, in __init__
    self.__connect(first_connect_check=True)
  File "/home/airflow/.local/lib/python3.7/site-packages/sqlalchemy/pool/base.py", line 605, in __connect
    pool.logger.debug("Error on connect(): %s", e)
  File "/home/airflow/.local/lib/python3.7/site-packages/sqlalchemy/util/langhelpers.py", line 72, in __exit__
    with_traceback=exc_tb,
  File "/home/airflow/.local/lib/python3.7/site-packages/sqlalchemy/util/compat.py", line 211, in raise_
    raise exception
  File "/home/airflow/.local/lib/python3.7/site-packages/sqlalchemy/pool/base.py", line 599, in __connect
    connection = pool._invoke_creator(self)
  File "/home/airflow/.local/lib/python3.7/site-packages/sqlalchemy/engine/create.py", line 578, in connect
    return dialect.connect(*cargs, **cparams)
  File "/home/airflow/.local/lib/python3.7/site-packages/sqlalchemy/engine/default.py", line 583, in connect
    return self.dbapi.connect(*cargs, **cparams)
  File "/home/airflow/.local/lib/python3.7/site-packages/psycopg2/__init__.py", line 122, in connect
    conn = _connect(dsn, connection_factory=connection_factory, **kwasync)
sqlalchemy.exc.OperationalError: (psycopg2.OperationalError) could not translate host name "pgdatabase" to address: Name or service not known

(Background on this error at: http://sqlalche.me/e/14/e3q8)
[2022-05-30 22:59:23,959] {taskinstance.py:1401} INFO - Marking task as FAILED. dag_id=LocalIngestionDag, task_id=ingest, execution_date=20220202T060000, start_date=20220530T225923, end_date=20220530T225923
[2022-05-30 22:59:23,972] {standard_task_runner.py:97} ERROR - Failed to execute job 16 for task ingest ((psycopg2.OperationalError) could not translate host name "pgdatabase" to address: Name or service not known

(Background on this error at: http://sqlalche.me/e/14/e3q8); 610)
[2022-05-30 22:59:23,991] {local_task_job.py:156} INFO - Task exited with return code 1
[2022-05-30 22:59:24,019] {local_task_job.py:273} INFO - 0 downstream tasks scheduled from follow-on schedule check
