[2022-05-31 18:07:56,120] {taskinstance.py:1160} INFO - Dependencies all met for <TaskInstance: yellow_taxi_ingestion_gcs_dag.local_to_gcs_task scheduled__2022-01-01T06:00:00+00:00 [queued]>
[2022-05-31 18:07:56,137] {taskinstance.py:1160} INFO - Dependencies all met for <TaskInstance: yellow_taxi_ingestion_gcs_dag.local_to_gcs_task scheduled__2022-01-01T06:00:00+00:00 [queued]>
[2022-05-31 18:07:56,141] {taskinstance.py:1357} INFO - 
--------------------------------------------------------------------------------
[2022-05-31 18:07:56,142] {taskinstance.py:1358} INFO - Starting attempt 1 of 1
[2022-05-31 18:07:56,144] {taskinstance.py:1359} INFO - 
--------------------------------------------------------------------------------
[2022-05-31 18:07:56,164] {taskinstance.py:1378} INFO - Executing <Task(PythonOperator): local_to_gcs_task> on 2022-01-01 06:00:00+00:00
[2022-05-31 18:07:56,176] {standard_task_runner.py:52} INFO - Started process 1044 to run task
[2022-05-31 18:07:56,181] {standard_task_runner.py:79} INFO - Running: ['***', 'tasks', 'run', 'yellow_taxi_ingestion_gcs_dag', 'local_to_gcs_task', 'scheduled__2022-01-01T06:00:00+00:00', '--job-id', '322', '--raw', '--subdir', 'DAGS_FOLDER/yellow_taxi_ingestion.py', '--cfg-path', '/tmp/tmp_l56lmvo', '--error-file', '/tmp/tmpy2dmto4c']
[2022-05-31 18:07:56,183] {standard_task_runner.py:80} INFO - Job 322: Subtask local_to_gcs_task
[2022-05-31 18:07:56,265] {task_command.py:370} INFO - Running <TaskInstance: yellow_taxi_ingestion_gcs_dag.local_to_gcs_task scheduled__2022-01-01T06:00:00+00:00 [running]> on host 8ac972de2f4f
[2022-05-31 18:07:56,312] {warnings.py:110} WARNING - /home/***/.local/lib/python3.7/site-packages/***/utils/context.py:202: AirflowContextDeprecationWarning: Accessing 'execution_date' from the template is deprecated and will be removed in a future version. Please use 'data_interval_start' or 'logical_date' instead.
  warnings.warn(_create_deprecation_warning(key, self._deprecation_replacements[key]))

[2022-05-31 18:07:56,369] {taskinstance.py:1572} INFO - Exporting the following env vars:
AIRFLOW_CTX_DAG_OWNER=***
AIRFLOW_CTX_DAG_ID=yellow_taxi_ingestion_gcs_dag
AIRFLOW_CTX_TASK_ID=local_to_gcs_task
AIRFLOW_CTX_EXECUTION_DATE=2022-01-01T06:00:00+00:00
AIRFLOW_CTX_TRY_NUMBER=1
AIRFLOW_CTX_DAG_RUN_ID=scheduled__2022-01-01T06:00:00+00:00
[2022-05-31 18:07:56,375] {taskinstance.py:1890} ERROR - Task failed with exception
Traceback (most recent call last):
  File "/home/airflow/.local/lib/python3.7/site-packages/airflow/operators/python.py", line 171, in execute
    return_value = self.execute_callable()
  File "/home/airflow/.local/lib/python3.7/site-packages/airflow/operators/python.py", line 189, in execute_callable
    return self.python_callable(*self.op_args, **self.op_kwargs)
  File "/opt/airflow/dags/yellow_taxi_ingestion.py", line 46, in upload_to_gcs
    client = storage.Client()
  File "/home/airflow/.local/lib/python3.7/site-packages/google/cloud/storage/client.py", line 128, in __init__
    _http=_http,
  File "/home/airflow/.local/lib/python3.7/site-packages/google/cloud/client/__init__.py", line 320, in __init__
    _ClientProjectMixin.__init__(self, project=project, credentials=credentials)
  File "/home/airflow/.local/lib/python3.7/site-packages/google/cloud/client/__init__.py", line 268, in __init__
    project = self._determine_default(project)
  File "/home/airflow/.local/lib/python3.7/site-packages/google/cloud/client/__init__.py", line 287, in _determine_default
    return _determine_default_project(project)
  File "/home/airflow/.local/lib/python3.7/site-packages/google/cloud/_helpers/__init__.py", line 152, in _determine_default_project
    _, project = google.auth.default()
  File "/home/airflow/.local/lib/python3.7/site-packages/google/auth/_default.py", line 546, in default
    credentials, project_id = checker()
  File "/home/airflow/.local/lib/python3.7/site-packages/google/auth/_default.py", line 539, in <lambda>
    lambda: _get_explicit_environ_credentials(quota_project_id=quota_project_id),
  File "/home/airflow/.local/lib/python3.7/site-packages/google/auth/_default.py", line 219, in _get_explicit_environ_credentials
    os.environ[environment_vars.CREDENTIALS], quota_project_id=quota_project_id
  File "/home/airflow/.local/lib/python3.7/site-packages/google/auth/_default.py", line 118, in load_credentials_from_file
    "File {} was not found.".format(filename)
google.auth.exceptions.DefaultCredentialsError: File ~/google/credentials/google_credentials.json was not found.
[2022-05-31 18:07:56,395] {taskinstance.py:1401} INFO - Marking task as FAILED. dag_id=yellow_taxi_ingestion_gcs_dag, task_id=local_to_gcs_task, execution_date=20220101T060000, start_date=20220531T180756, end_date=20220531T180756
[2022-05-31 18:07:56,409] {standard_task_runner.py:97} ERROR - Failed to execute job 322 for task local_to_gcs_task (File ~/google/credentials/google_credentials.json was not found.; 1044)
[2022-05-31 18:07:56,437] {local_task_job.py:156} INFO - Task exited with return code 1
[2022-05-31 18:07:56,500] {local_task_job.py:273} INFO - 0 downstream tasks scheduled from follow-on schedule check
[2022-05-31 18:50:01,355] {taskinstance.py:1160} INFO - Dependencies all met for <TaskInstance: yellow_taxi_ingestion_gcs_dag.local_to_gcs_task scheduled__2022-01-01T06:00:00+00:00 [queued]>
[2022-05-31 18:50:01,397] {taskinstance.py:1160} INFO - Dependencies all met for <TaskInstance: yellow_taxi_ingestion_gcs_dag.local_to_gcs_task scheduled__2022-01-01T06:00:00+00:00 [queued]>
[2022-05-31 18:50:01,401] {taskinstance.py:1357} INFO - 
--------------------------------------------------------------------------------
[2022-05-31 18:50:01,405] {taskinstance.py:1358} INFO - Starting attempt 1 of 1
[2022-05-31 18:50:01,406] {taskinstance.py:1359} INFO - 
--------------------------------------------------------------------------------
[2022-05-31 18:50:01,453] {taskinstance.py:1378} INFO - Executing <Task(PythonOperator): local_to_gcs_task> on 2022-01-01 06:00:00+00:00
[2022-05-31 18:50:01,475] {standard_task_runner.py:52} INFO - Started process 1189 to run task
[2022-05-31 18:50:01,489] {standard_task_runner.py:79} INFO - Running: ['***', 'tasks', 'run', 'yellow_taxi_ingestion_gcs_dag', 'local_to_gcs_task', 'scheduled__2022-01-01T06:00:00+00:00', '--job-id', '415', '--raw', '--subdir', 'DAGS_FOLDER/yellow_taxi_ingestion.py', '--cfg-path', '/tmp/tmp6n9ybto2', '--error-file', '/tmp/tmpf3pspepw']
[2022-05-31 18:50:01,497] {standard_task_runner.py:80} INFO - Job 415: Subtask local_to_gcs_task
[2022-05-31 18:50:01,654] {task_command.py:370} INFO - Running <TaskInstance: yellow_taxi_ingestion_gcs_dag.local_to_gcs_task scheduled__2022-01-01T06:00:00+00:00 [running]> on host 3f188d455d5a
[2022-05-31 18:50:01,733] {warnings.py:110} WARNING - /home/***/.local/lib/python3.7/site-packages/***/utils/context.py:202: AirflowContextDeprecationWarning: Accessing 'execution_date' from the template is deprecated and will be removed in a future version. Please use 'data_interval_start' or 'logical_date' instead.
  warnings.warn(_create_deprecation_warning(key, self._deprecation_replacements[key]))

[2022-05-31 18:50:01,841] {taskinstance.py:1572} INFO - Exporting the following env vars:
AIRFLOW_CTX_DAG_OWNER=***
AIRFLOW_CTX_DAG_ID=yellow_taxi_ingestion_gcs_dag
AIRFLOW_CTX_TASK_ID=local_to_gcs_task
AIRFLOW_CTX_EXECUTION_DATE=2022-01-01T06:00:00+00:00
AIRFLOW_CTX_TRY_NUMBER=1
AIRFLOW_CTX_DAG_RUN_ID=scheduled__2022-01-01T06:00:00+00:00
[2022-05-31 18:50:06,103] {python.py:173} INFO - Done. Returned value was: None
[2022-05-31 18:50:06,147] {taskinstance.py:1401} INFO - Marking task as SUCCESS. dag_id=yellow_taxi_ingestion_gcs_dag, task_id=local_to_gcs_task, execution_date=20220101T060000, start_date=20220531T185001, end_date=20220531T185006
[2022-05-31 18:50:06,215] {local_task_job.py:156} INFO - Task exited with return code 0
[2022-05-31 18:50:06,271] {local_task_job.py:273} INFO - 0 downstream tasks scheduled from follow-on schedule check
