[2022-05-30 18:50:15,575] {taskinstance.py:1160} INFO - Dependencies all met for <TaskInstance: data_ingestion_gcs_dag.local_to_gcs_task manual__2022-05-30T18:44:49.112568+00:00 [queued]>
[2022-05-30 18:50:15,600] {taskinstance.py:1160} INFO - Dependencies all met for <TaskInstance: data_ingestion_gcs_dag.local_to_gcs_task manual__2022-05-30T18:44:49.112568+00:00 [queued]>
[2022-05-30 18:50:15,602] {taskinstance.py:1357} INFO - 
--------------------------------------------------------------------------------
[2022-05-30 18:50:15,604] {taskinstance.py:1358} INFO - Starting attempt 2 of 2
[2022-05-30 18:50:15,606] {taskinstance.py:1359} INFO - 
--------------------------------------------------------------------------------
[2022-05-30 18:50:15,657] {taskinstance.py:1378} INFO - Executing <Task(PythonOperator): local_to_gcs_task> on 2022-05-30 18:44:49.112568+00:00
[2022-05-30 18:50:15,711] {standard_task_runner.py:52} INFO - Started process 63 to run task
[2022-05-30 18:50:15,721] {standard_task_runner.py:79} INFO - Running: ['***', 'tasks', 'run', 'data_ingestion_gcs_dag', 'local_to_gcs_task', 'manual__2022-05-30T18:44:49.112568+00:00', '--job-id', '28', '--raw', '--subdir', 'DAGS_FOLDER/data_ingestion_gcs_dag.py', '--cfg-path', '/tmp/tmpp99_dzia', '--error-file', '/tmp/tmp50t4hbr6']
[2022-05-30 18:50:15,727] {standard_task_runner.py:80} INFO - Job 28: Subtask local_to_gcs_task
[2022-05-30 18:50:15,834] {task_command.py:370} INFO - Running <TaskInstance: data_ingestion_gcs_dag.local_to_gcs_task manual__2022-05-30T18:44:49.112568+00:00 [running]> on host e083cbf9476b
[2022-05-30 18:50:15,935] {taskinstance.py:1572} INFO - Exporting the following env vars:
AIRFLOW_CTX_DAG_OWNER=***
AIRFLOW_CTX_DAG_ID=data_ingestion_gcs_dag
AIRFLOW_CTX_TASK_ID=local_to_gcs_task
AIRFLOW_CTX_EXECUTION_DATE=2022-05-30T18:44:49.112568+00:00
AIRFLOW_CTX_TRY_NUMBER=2
AIRFLOW_CTX_DAG_RUN_ID=manual__2022-05-30T18:44:49.112568+00:00
[2022-05-30 18:50:15,986] {taskinstance.py:1890} ERROR - Task failed with exception
Traceback (most recent call last):
  File "/home/airflow/.local/lib/python3.7/site-packages/airflow/operators/python.py", line 171, in execute
    return_value = self.execute_callable()
  File "/home/airflow/.local/lib/python3.7/site-packages/airflow/operators/python.py", line 189, in execute_callable
    return self.python_callable(*self.op_args, **self.op_kwargs)
  File "/opt/airflow/dags/data_ingestion_gcs_dag.py", line 51, in upload_to_gcs
    blob.upload_from_filename(local_file)
  File "/home/airflow/.local/lib/python3.7/site-packages/google/cloud/storage/blob.py", line 2720, in upload_from_filename
    with open(filename, "rb") as file_obj:
FileNotFoundError: [Errno 2] No such file or directory: '/opt/airflow/yellow_tripdata_2021-01.parquet'
[2022-05-30 18:50:16,005] {taskinstance.py:1401} INFO - Marking task as FAILED. dag_id=data_ingestion_gcs_dag, task_id=local_to_gcs_task, execution_date=20220530T184449, start_date=20220530T185015, end_date=20220530T185016
[2022-05-30 18:50:16,017] {standard_task_runner.py:97} ERROR - Failed to execute job 28 for task local_to_gcs_task ([Errno 2] No such file or directory: '/opt/airflow/yellow_tripdata_2021-01.parquet'; 63)
[2022-05-30 18:50:16,064] {local_task_job.py:156} INFO - Task exited with return code 1
[2022-05-30 18:50:16,111] {local_task_job.py:273} INFO - 0 downstream tasks scheduled from follow-on schedule check
