[2022-05-30 20:21:46,406] {taskinstance.py:1160} INFO - Dependencies all met for <TaskInstance: LocalIngestionDag.ingest scheduled__2022-04-02T06:00:00+00:00 [queued]>
[2022-05-30 20:21:46,416] {taskinstance.py:1160} INFO - Dependencies all met for <TaskInstance: LocalIngestionDag.ingest scheduled__2022-04-02T06:00:00+00:00 [queued]>
[2022-05-30 20:21:46,419] {taskinstance.py:1357} INFO - 
--------------------------------------------------------------------------------
[2022-05-30 20:21:46,420] {taskinstance.py:1358} INFO - Starting attempt 1 of 1
[2022-05-30 20:21:46,421] {taskinstance.py:1359} INFO - 
--------------------------------------------------------------------------------
[2022-05-30 20:21:46,446] {taskinstance.py:1378} INFO - Executing <Task(PythonOperator): ingest> on 2022-04-02 06:00:00+00:00
[2022-05-30 20:21:46,459] {standard_task_runner.py:52} INFO - Started process 1319 to run task
[2022-05-30 20:21:46,468] {standard_task_runner.py:79} INFO - Running: ['***', 'tasks', 'run', 'LocalIngestionDag', 'ingest', 'scheduled__2022-04-02T06:00:00+00:00', '--job-id', '149', '--raw', '--subdir', 'DAGS_FOLDER/data_ingestion_local.py', '--cfg-path', '/tmp/tmp7xjb_hh4', '--error-file', '/tmp/tmp0cg_z9kw']
[2022-05-30 20:21:46,473] {standard_task_runner.py:80} INFO - Job 149: Subtask ingest
[2022-05-30 20:21:46,556] {task_command.py:370} INFO - Running <TaskInstance: LocalIngestionDag.ingest scheduled__2022-04-02T06:00:00+00:00 [running]> on host e083cbf9476b
[2022-05-30 20:21:46,588] {warnings.py:110} WARNING - /home/***/.local/lib/python3.7/site-packages/***/utils/context.py:202: AirflowContextDeprecationWarning: Accessing 'execution_date' from the template is deprecated and will be removed in a future version. Please use 'data_interval_start' or 'logical_date' instead.
  warnings.warn(_create_deprecation_warning(key, self._deprecation_replacements[key]))

[2022-05-30 20:21:46,626] {taskinstance.py:1572} INFO - Exporting the following env vars:
AIRFLOW_CTX_DAG_OWNER=***
AIRFLOW_CTX_DAG_ID=LocalIngestionDag
AIRFLOW_CTX_TASK_ID=ingest
AIRFLOW_CTX_EXECUTION_DATE=2022-04-02T06:00:00+00:00
AIRFLOW_CTX_TRY_NUMBER=1
AIRFLOW_CTX_DAG_RUN_ID=scheduled__2022-04-02T06:00:00+00:00
[2022-05-30 20:21:46,628] {logging_mixin.py:115} INFO - yellow_taxi_2022_04 /opt/***/output_2022-04.parquet 2022-04-02T06:00:00+00:00
[2022-05-30 20:21:46,629] {taskinstance.py:1890} ERROR - Task failed with exception
Traceback (most recent call last):
  File "/home/airflow/.local/lib/python3.7/site-packages/airflow/operators/python.py", line 171, in execute
    return_value = self.execute_callable()
  File "/home/airflow/.local/lib/python3.7/site-packages/airflow/operators/python.py", line 189, in execute_callable
    return self.python_callable(*self.op_args, **self.op_kwargs)
  File "/opt/airflow/dags/ingest_script.py", line 12, in ingest_callable
    engine = create_engine(f'postgresql://{user}:{password}@{host}:{port}/{db}')
  File "<string>", line 2, in create_engine
  File "/home/airflow/.local/lib/python3.7/site-packages/sqlalchemy/util/deprecations.py", line 298, in warned
    return fn(*args, **kwargs)
  File "/home/airflow/.local/lib/python3.7/site-packages/sqlalchemy/engine/create.py", line 518, in create_engine
    u = _url.make_url(url)
  File "/home/airflow/.local/lib/python3.7/site-packages/sqlalchemy/engine/url.py", line 711, in make_url
    return _parse_rfc1738_args(name_or_url)
  File "/home/airflow/.local/lib/python3.7/site-packages/sqlalchemy/engine/url.py", line 772, in _parse_rfc1738_args
    components["port"] = int(components["port"])
ValueError: invalid literal for int() with base 10: 'None'
[2022-05-30 20:21:46,641] {taskinstance.py:1401} INFO - Marking task as FAILED. dag_id=LocalIngestionDag, task_id=ingest, execution_date=20220402T060000, start_date=20220530T202146, end_date=20220530T202146
[2022-05-30 20:21:46,651] {standard_task_runner.py:97} ERROR - Failed to execute job 149 for task ingest (invalid literal for int() with base 10: 'None'; 1319)
[2022-05-30 20:21:46,682] {local_task_job.py:156} INFO - Task exited with return code 1
[2022-05-30 20:21:46,715] {local_task_job.py:273} INFO - 0 downstream tasks scheduled from follow-on schedule check
[2022-05-30 20:28:26,183] {taskinstance.py:1160} INFO - Dependencies all met for <TaskInstance: LocalIngestionDag.ingest scheduled__2022-04-02T06:00:00+00:00 [queued]>
[2022-05-30 20:28:26,196] {taskinstance.py:1160} INFO - Dependencies all met for <TaskInstance: LocalIngestionDag.ingest scheduled__2022-04-02T06:00:00+00:00 [queued]>
[2022-05-30 20:28:26,197] {taskinstance.py:1357} INFO - 
--------------------------------------------------------------------------------
[2022-05-30 20:28:26,199] {taskinstance.py:1358} INFO - Starting attempt 1 of 1
[2022-05-30 20:28:26,200] {taskinstance.py:1359} INFO - 
--------------------------------------------------------------------------------
[2022-05-30 20:28:26,219] {taskinstance.py:1378} INFO - Executing <Task(PythonOperator): ingest> on 2022-04-02 06:00:00+00:00
[2022-05-30 20:28:26,250] {standard_task_runner.py:52} INFO - Started process 1707 to run task
[2022-05-30 20:28:26,275] {standard_task_runner.py:79} INFO - Running: ['***', 'tasks', 'run', 'LocalIngestionDag', 'ingest', 'scheduled__2022-04-02T06:00:00+00:00', '--job-id', '156', '--raw', '--subdir', 'DAGS_FOLDER/data_ingestion_local.py', '--cfg-path', '/tmp/tmpuoq5r8qc', '--error-file', '/tmp/tmpifgdvlre']
[2022-05-30 20:28:26,278] {standard_task_runner.py:80} INFO - Job 156: Subtask ingest
[2022-05-30 20:28:26,380] {task_command.py:370} INFO - Running <TaskInstance: LocalIngestionDag.ingest scheduled__2022-04-02T06:00:00+00:00 [running]> on host e083cbf9476b
[2022-05-30 20:28:26,426] {warnings.py:110} WARNING - /home/***/.local/lib/python3.7/site-packages/***/utils/context.py:202: AirflowContextDeprecationWarning: Accessing 'execution_date' from the template is deprecated and will be removed in a future version. Please use 'data_interval_start' or 'logical_date' instead.
  warnings.warn(_create_deprecation_warning(key, self._deprecation_replacements[key]))

[2022-05-30 20:28:26,475] {taskinstance.py:1572} INFO - Exporting the following env vars:
AIRFLOW_CTX_DAG_OWNER=***
AIRFLOW_CTX_DAG_ID=LocalIngestionDag
AIRFLOW_CTX_TASK_ID=ingest
AIRFLOW_CTX_EXECUTION_DATE=2022-04-02T06:00:00+00:00
AIRFLOW_CTX_TRY_NUMBER=1
AIRFLOW_CTX_DAG_RUN_ID=scheduled__2022-04-02T06:00:00+00:00
[2022-05-30 20:28:26,481] {logging_mixin.py:115} INFO - yellow_taxi_2022_04 /opt/***/output_2022-04.parquet 2022-04-02T06:00:00+00:00
[2022-05-30 20:28:26,483] {taskinstance.py:1890} ERROR - Task failed with exception
Traceback (most recent call last):
  File "/home/airflow/.local/lib/python3.7/site-packages/airflow/operators/python.py", line 171, in execute
    return_value = self.execute_callable()
  File "/home/airflow/.local/lib/python3.7/site-packages/airflow/operators/python.py", line 189, in execute_callable
    return self.python_callable(*self.op_args, **self.op_kwargs)
  File "/opt/airflow/dags/ingest_script.py", line 12, in ingest_callable
    engine = create_engine(f'postgresql://{user}:{password}@{host}:{port}/{db}')
  File "<string>", line 2, in create_engine
  File "/home/airflow/.local/lib/python3.7/site-packages/sqlalchemy/util/deprecations.py", line 298, in warned
    return fn(*args, **kwargs)
  File "/home/airflow/.local/lib/python3.7/site-packages/sqlalchemy/engine/create.py", line 518, in create_engine
    u = _url.make_url(url)
  File "/home/airflow/.local/lib/python3.7/site-packages/sqlalchemy/engine/url.py", line 711, in make_url
    return _parse_rfc1738_args(name_or_url)
  File "/home/airflow/.local/lib/python3.7/site-packages/sqlalchemy/engine/url.py", line 772, in _parse_rfc1738_args
    components["port"] = int(components["port"])
ValueError: invalid literal for int() with base 10: 'None'
[2022-05-30 20:28:26,504] {taskinstance.py:1401} INFO - Marking task as FAILED. dag_id=LocalIngestionDag, task_id=ingest, execution_date=20220402T060000, start_date=20220530T202826, end_date=20220530T202826
[2022-05-30 20:28:26,528] {standard_task_runner.py:97} ERROR - Failed to execute job 156 for task ingest (invalid literal for int() with base 10: 'None'; 1707)
[2022-05-30 20:28:26,568] {local_task_job.py:156} INFO - Task exited with return code 1
[2022-05-30 20:28:26,801] {local_task_job.py:273} INFO - 0 downstream tasks scheduled from follow-on schedule check
[2022-05-30 21:14:05,004] {taskinstance.py:1160} INFO - Dependencies all met for <TaskInstance: LocalIngestionDag.ingest scheduled__2022-04-02T06:00:00+00:00 [queued]>
[2022-05-30 21:14:05,029] {taskinstance.py:1160} INFO - Dependencies all met for <TaskInstance: LocalIngestionDag.ingest scheduled__2022-04-02T06:00:00+00:00 [queued]>
[2022-05-30 21:14:05,030] {taskinstance.py:1357} INFO - 
--------------------------------------------------------------------------------
[2022-05-30 21:14:05,032] {taskinstance.py:1358} INFO - Starting attempt 1 of 1
[2022-05-30 21:14:05,034] {taskinstance.py:1359} INFO - 
--------------------------------------------------------------------------------
[2022-05-30 21:14:05,055] {taskinstance.py:1378} INFO - Executing <Task(PythonOperator): ingest> on 2022-04-02 06:00:00+00:00
[2022-05-30 21:14:05,101] {standard_task_runner.py:52} INFO - Started process 277 to run task
[2022-05-30 21:14:05,116] {standard_task_runner.py:79} INFO - Running: ['***', 'tasks', 'run', 'LocalIngestionDag', 'ingest', 'scheduled__2022-04-02T06:00:00+00:00', '--job-id', '9', '--raw', '--subdir', 'DAGS_FOLDER/data_ingestion_local.py', '--cfg-path', '/tmp/tmpu7dtp0s8', '--error-file', '/tmp/tmpi6b2zcb7']
[2022-05-30 21:14:05,121] {standard_task_runner.py:80} INFO - Job 9: Subtask ingest
[2022-05-30 21:14:05,240] {task_command.py:370} INFO - Running <TaskInstance: LocalIngestionDag.ingest scheduled__2022-04-02T06:00:00+00:00 [running]> on host 973151ef250d
[2022-05-30 21:14:05,372] {warnings.py:110} WARNING - /home/***/.local/lib/python3.7/site-packages/***/utils/context.py:202: AirflowContextDeprecationWarning: Accessing 'execution_date' from the template is deprecated and will be removed in a future version. Please use 'data_interval_start' or 'logical_date' instead.
  warnings.warn(_create_deprecation_warning(key, self._deprecation_replacements[key]))

[2022-05-30 21:14:05,543] {taskinstance.py:1572} INFO - Exporting the following env vars:
AIRFLOW_CTX_DAG_OWNER=***
AIRFLOW_CTX_DAG_ID=LocalIngestionDag
AIRFLOW_CTX_TASK_ID=ingest
AIRFLOW_CTX_EXECUTION_DATE=2022-04-02T06:00:00+00:00
AIRFLOW_CTX_TRY_NUMBER=1
AIRFLOW_CTX_DAG_RUN_ID=scheduled__2022-04-02T06:00:00+00:00
[2022-05-30 21:14:05,560] {logging_mixin.py:115} INFO - yellow_taxi_2022_04 /opt/***/output_2022-04.parquet 2022-04-02T06:00:00+00:00
[2022-05-30 21:14:05,597] {taskinstance.py:1890} ERROR - Task failed with exception
Traceback (most recent call last):
  File "/home/airflow/.local/lib/python3.7/site-packages/sqlalchemy/engine/base.py", line 3141, in _wrap_pool_connect
    return fn()
  File "/home/airflow/.local/lib/python3.7/site-packages/sqlalchemy/pool/base.py", line 301, in connect
    return _ConnectionFairy._checkout(self)
  File "/home/airflow/.local/lib/python3.7/site-packages/sqlalchemy/pool/base.py", line 755, in _checkout
    fairy = _ConnectionRecord.checkout(pool)
  File "/home/airflow/.local/lib/python3.7/site-packages/sqlalchemy/pool/base.py", line 419, in checkout
    rec = pool._do_get()
  File "/home/airflow/.local/lib/python3.7/site-packages/sqlalchemy/pool/impl.py", line 145, in _do_get
    self._dec_overflow()
  File "/home/airflow/.local/lib/python3.7/site-packages/sqlalchemy/util/langhelpers.py", line 72, in __exit__
    with_traceback=exc_tb,
  File "/home/airflow/.local/lib/python3.7/site-packages/sqlalchemy/util/compat.py", line 211, in raise_
    raise exception
  File "/home/airflow/.local/lib/python3.7/site-packages/sqlalchemy/pool/impl.py", line 142, in _do_get
    return self._create_connection()
  File "/home/airflow/.local/lib/python3.7/site-packages/sqlalchemy/pool/base.py", line 247, in _create_connection
    return _ConnectionRecord(self)
  File "/home/airflow/.local/lib/python3.7/site-packages/sqlalchemy/pool/base.py", line 362, in __init__
    self.__connect(first_connect_check=True)
  File "/home/airflow/.local/lib/python3.7/site-packages/sqlalchemy/pool/base.py", line 605, in __connect
    pool.logger.debug("Error on connect(): %s", e)
  File "/home/airflow/.local/lib/python3.7/site-packages/sqlalchemy/util/langhelpers.py", line 72, in __exit__
    with_traceback=exc_tb,
  File "/home/airflow/.local/lib/python3.7/site-packages/sqlalchemy/util/compat.py", line 211, in raise_
    raise exception
  File "/home/airflow/.local/lib/python3.7/site-packages/sqlalchemy/pool/base.py", line 599, in __connect
    connection = pool._invoke_creator(self)
  File "/home/airflow/.local/lib/python3.7/site-packages/sqlalchemy/engine/create.py", line 578, in connect
    return dialect.connect(*cargs, **cparams)
  File "/home/airflow/.local/lib/python3.7/site-packages/sqlalchemy/engine/default.py", line 583, in connect
    return self.dbapi.connect(*cargs, **cparams)
  File "/home/airflow/.local/lib/python3.7/site-packages/psycopg2/__init__.py", line 122, in connect
    conn = _connect(dsn, connection_factory=connection_factory, **kwasync)
psycopg2.OperationalError: could not translate host name "pgdatabase" to address: Name or service not known


The above exception was the direct cause of the following exception:

Traceback (most recent call last):
  File "/home/airflow/.local/lib/python3.7/site-packages/airflow/operators/python.py", line 171, in execute
    return_value = self.execute_callable()
  File "/home/airflow/.local/lib/python3.7/site-packages/airflow/operators/python.py", line 189, in execute_callable
    return self.python_callable(*self.op_args, **self.op_kwargs)
  File "/opt/airflow/dags/ingest_script.py", line 13, in ingest_callable
    engine.connect()
  File "/home/airflow/.local/lib/python3.7/site-packages/sqlalchemy/engine/base.py", line 3095, in connect
    return self._connection_cls(self, close_with_result=close_with_result)
  File "/home/airflow/.local/lib/python3.7/site-packages/sqlalchemy/engine/base.py", line 91, in __init__
    else engine.raw_connection()
  File "/home/airflow/.local/lib/python3.7/site-packages/sqlalchemy/engine/base.py", line 3174, in raw_connection
    return self._wrap_pool_connect(self.pool.connect, _connection)
  File "/home/airflow/.local/lib/python3.7/site-packages/sqlalchemy/engine/base.py", line 3145, in _wrap_pool_connect
    e, dialect, self
  File "/home/airflow/.local/lib/python3.7/site-packages/sqlalchemy/engine/base.py", line 2004, in _handle_dbapi_exception_noconnection
    sqlalchemy_exception, with_traceback=exc_info[2], from_=e
  File "/home/airflow/.local/lib/python3.7/site-packages/sqlalchemy/util/compat.py", line 211, in raise_
    raise exception
  File "/home/airflow/.local/lib/python3.7/site-packages/sqlalchemy/engine/base.py", line 3141, in _wrap_pool_connect
    return fn()
  File "/home/airflow/.local/lib/python3.7/site-packages/sqlalchemy/pool/base.py", line 301, in connect
    return _ConnectionFairy._checkout(self)
  File "/home/airflow/.local/lib/python3.7/site-packages/sqlalchemy/pool/base.py", line 755, in _checkout
    fairy = _ConnectionRecord.checkout(pool)
  File "/home/airflow/.local/lib/python3.7/site-packages/sqlalchemy/pool/base.py", line 419, in checkout
    rec = pool._do_get()
  File "/home/airflow/.local/lib/python3.7/site-packages/sqlalchemy/pool/impl.py", line 145, in _do_get
    self._dec_overflow()
  File "/home/airflow/.local/lib/python3.7/site-packages/sqlalchemy/util/langhelpers.py", line 72, in __exit__
    with_traceback=exc_tb,
  File "/home/airflow/.local/lib/python3.7/site-packages/sqlalchemy/util/compat.py", line 211, in raise_
    raise exception
  File "/home/airflow/.local/lib/python3.7/site-packages/sqlalchemy/pool/impl.py", line 142, in _do_get
    return self._create_connection()
  File "/home/airflow/.local/lib/python3.7/site-packages/sqlalchemy/pool/base.py", line 247, in _create_connection
    return _ConnectionRecord(self)
  File "/home/airflow/.local/lib/python3.7/site-packages/sqlalchemy/pool/base.py", line 362, in __init__
    self.__connect(first_connect_check=True)
  File "/home/airflow/.local/lib/python3.7/site-packages/sqlalchemy/pool/base.py", line 605, in __connect
    pool.logger.debug("Error on connect(): %s", e)
  File "/home/airflow/.local/lib/python3.7/site-packages/sqlalchemy/util/langhelpers.py", line 72, in __exit__
    with_traceback=exc_tb,
  File "/home/airflow/.local/lib/python3.7/site-packages/sqlalchemy/util/compat.py", line 211, in raise_
    raise exception
  File "/home/airflow/.local/lib/python3.7/site-packages/sqlalchemy/pool/base.py", line 599, in __connect
    connection = pool._invoke_creator(self)
  File "/home/airflow/.local/lib/python3.7/site-packages/sqlalchemy/engine/create.py", line 578, in connect
    return dialect.connect(*cargs, **cparams)
  File "/home/airflow/.local/lib/python3.7/site-packages/sqlalchemy/engine/default.py", line 583, in connect
    return self.dbapi.connect(*cargs, **cparams)
  File "/home/airflow/.local/lib/python3.7/site-packages/psycopg2/__init__.py", line 122, in connect
    conn = _connect(dsn, connection_factory=connection_factory, **kwasync)
sqlalchemy.exc.OperationalError: (psycopg2.OperationalError) could not translate host name "pgdatabase" to address: Name or service not known

(Background on this error at: http://sqlalche.me/e/14/e3q8)
[2022-05-30 21:14:05,736] {taskinstance.py:1401} INFO - Marking task as FAILED. dag_id=LocalIngestionDag, task_id=ingest, execution_date=20220402T060000, start_date=20220530T211405, end_date=20220530T211405
[2022-05-30 21:14:05,805] {standard_task_runner.py:97} ERROR - Failed to execute job 9 for task ingest ((psycopg2.OperationalError) could not translate host name "pgdatabase" to address: Name or service not known

(Background on this error at: http://sqlalche.me/e/14/e3q8); 277)
[2022-05-30 21:14:05,902] {local_task_job.py:156} INFO - Task exited with return code 1
[2022-05-30 21:14:05,991] {local_task_job.py:273} INFO - 0 downstream tasks scheduled from follow-on schedule check
[2022-05-30 22:12:15,018] {taskinstance.py:1160} INFO - Dependencies all met for <TaskInstance: LocalIngestionDag.ingest scheduled__2022-04-02T06:00:00+00:00 [queued]>
[2022-05-30 22:12:15,123] {taskinstance.py:1160} INFO - Dependencies all met for <TaskInstance: LocalIngestionDag.ingest scheduled__2022-04-02T06:00:00+00:00 [queued]>
[2022-05-30 22:12:15,137] {taskinstance.py:1357} INFO - 
--------------------------------------------------------------------------------
[2022-05-30 22:12:15,154] {taskinstance.py:1358} INFO - Starting attempt 1 of 1
[2022-05-30 22:12:15,156] {taskinstance.py:1359} INFO - 
--------------------------------------------------------------------------------
[2022-05-30 22:12:15,308] {taskinstance.py:1378} INFO - Executing <Task(PythonOperator): ingest> on 2022-04-02 06:00:00+00:00
[2022-05-30 22:12:15,385] {standard_task_runner.py:52} INFO - Started process 996 to run task
[2022-05-30 22:12:15,431] {standard_task_runner.py:79} INFO - Running: ['***', 'tasks', 'run', 'LocalIngestionDag', 'ingest', 'scheduled__2022-04-02T06:00:00+00:00', '--job-id', '194', '--raw', '--subdir', 'DAGS_FOLDER/data_ingestion_local.py', '--cfg-path', '/tmp/tmp_kn7pfdx', '--error-file', '/tmp/tmpnect7xvu']
[2022-05-30 22:12:15,444] {standard_task_runner.py:80} INFO - Job 194: Subtask ingest
[2022-05-30 22:12:15,685] {task_command.py:370} INFO - Running <TaskInstance: LocalIngestionDag.ingest scheduled__2022-04-02T06:00:00+00:00 [running]> on host 8ac972de2f4f
[2022-05-30 22:12:15,815] {warnings.py:110} WARNING - /home/***/.local/lib/python3.7/site-packages/***/utils/context.py:202: AirflowContextDeprecationWarning: Accessing 'execution_date' from the template is deprecated and will be removed in a future version. Please use 'data_interval_start' or 'logical_date' instead.
  warnings.warn(_create_deprecation_warning(key, self._deprecation_replacements[key]))

[2022-05-30 22:12:16,042] {taskinstance.py:1572} INFO - Exporting the following env vars:
AIRFLOW_CTX_DAG_OWNER=***
AIRFLOW_CTX_DAG_ID=LocalIngestionDag
AIRFLOW_CTX_TASK_ID=ingest
AIRFLOW_CTX_EXECUTION_DATE=2022-04-02T06:00:00+00:00
AIRFLOW_CTX_TRY_NUMBER=1
AIRFLOW_CTX_DAG_RUN_ID=scheduled__2022-04-02T06:00:00+00:00
[2022-05-30 22:12:16,060] {logging_mixin.py:115} INFO - yellow_taxi_2022_04 /opt/***/output_2022-04.parquet 2022-04-02T06:00:00+00:00
[2022-05-30 22:12:16,172] {logging_mixin.py:115} INFO - connection established successfully, inserting data...
[2022-05-30 22:12:16,529] {taskinstance.py:1890} ERROR - Task failed with exception
Traceback (most recent call last):
  File "/home/airflow/.local/lib/python3.7/site-packages/airflow/operators/python.py", line 171, in execute
    return_value = self.execute_callable()
  File "/home/airflow/.local/lib/python3.7/site-packages/airflow/operators/python.py", line 189, in execute_callable
    return self.python_callable(*self.op_args, **self.op_kwargs)
  File "/opt/airflow/dags/ingest_script.py", line 18, in ingest_callable
    df_iter = pd.read_parquet(parquet_file)
  File "/home/airflow/.local/lib/python3.7/site-packages/pandas/io/parquet.py", line 500, in read_parquet
    **kwargs,
  File "/home/airflow/.local/lib/python3.7/site-packages/pandas/io/parquet.py", line 240, in read
    path_or_handle, columns=columns, **kwargs
  File "/home/airflow/.local/lib/python3.7/site-packages/pyarrow/parquet.py", line 1915, in read_table
    coerce_int96_timestamp_unit=coerce_int96_timestamp_unit
  File "/home/airflow/.local/lib/python3.7/site-packages/pyarrow/parquet.py", line 1711, in __init__
    [fragment], schema=fragment.physical_schema,
  File "pyarrow/_dataset.pyx", line 978, in pyarrow._dataset.Fragment.physical_schema.__get__
  File "pyarrow/error.pxi", line 143, in pyarrow.lib.pyarrow_internal_check_status
  File "pyarrow/error.pxi", line 99, in pyarrow.lib.check_status
pyarrow.lib.ArrowInvalid: Could not open Parquet input source '<Buffer>': Parquet magic bytes not found in footer. Either the file is corrupted or this is not a parquet file.
[2022-05-30 22:12:16,639] {taskinstance.py:1401} INFO - Marking task as FAILED. dag_id=LocalIngestionDag, task_id=ingest, execution_date=20220402T060000, start_date=20220530T221215, end_date=20220530T221216
[2022-05-30 22:12:16,687] {standard_task_runner.py:97} ERROR - Failed to execute job 194 for task ingest (Could not open Parquet input source '<Buffer>': Parquet magic bytes not found in footer. Either the file is corrupted or this is not a parquet file.; 996)
[2022-05-30 22:12:16,789] {local_task_job.py:156} INFO - Task exited with return code 1
[2022-05-30 22:12:16,977] {local_task_job.py:273} INFO - 0 downstream tasks scheduled from follow-on schedule check
[2022-05-30 22:16:53,685] {taskinstance.py:1160} INFO - Dependencies all met for <TaskInstance: LocalIngestionDag.ingest scheduled__2022-04-02T06:00:00+00:00 [queued]>
[2022-05-30 22:16:53,709] {taskinstance.py:1160} INFO - Dependencies all met for <TaskInstance: LocalIngestionDag.ingest scheduled__2022-04-02T06:00:00+00:00 [queued]>
[2022-05-30 22:16:53,711] {taskinstance.py:1357} INFO - 
--------------------------------------------------------------------------------
[2022-05-30 22:16:53,713] {taskinstance.py:1358} INFO - Starting attempt 1 of 1
[2022-05-30 22:16:53,714] {taskinstance.py:1359} INFO - 
--------------------------------------------------------------------------------
[2022-05-30 22:16:53,841] {taskinstance.py:1378} INFO - Executing <Task(PythonOperator): ingest> on 2022-04-02 06:00:00+00:00
[2022-05-30 22:16:53,954] {standard_task_runner.py:52} INFO - Started process 1347 to run task
[2022-05-30 22:16:53,979] {standard_task_runner.py:79} INFO - Running: ['***', 'tasks', 'run', 'LocalIngestionDag', 'ingest', 'scheduled__2022-04-02T06:00:00+00:00', '--job-id', '216', '--raw', '--subdir', 'DAGS_FOLDER/data_ingestion_local.py', '--cfg-path', '/tmp/tmplhre5fjo', '--error-file', '/tmp/tmpji3wzfqn']
[2022-05-30 22:16:53,985] {standard_task_runner.py:80} INFO - Job 216: Subtask ingest
[2022-05-30 22:16:54,261] {task_command.py:370} INFO - Running <TaskInstance: LocalIngestionDag.ingest scheduled__2022-04-02T06:00:00+00:00 [running]> on host 8ac972de2f4f
[2022-05-30 22:16:54,411] {warnings.py:110} WARNING - /home/***/.local/lib/python3.7/site-packages/***/utils/context.py:202: AirflowContextDeprecationWarning: Accessing 'execution_date' from the template is deprecated and will be removed in a future version. Please use 'data_interval_start' or 'logical_date' instead.
  warnings.warn(_create_deprecation_warning(key, self._deprecation_replacements[key]))

[2022-05-30 22:16:54,620] {taskinstance.py:1572} INFO - Exporting the following env vars:
AIRFLOW_CTX_DAG_OWNER=***
AIRFLOW_CTX_DAG_ID=LocalIngestionDag
AIRFLOW_CTX_TASK_ID=ingest
AIRFLOW_CTX_EXECUTION_DATE=2022-04-02T06:00:00+00:00
AIRFLOW_CTX_TRY_NUMBER=1
AIRFLOW_CTX_DAG_RUN_ID=scheduled__2022-04-02T06:00:00+00:00
[2022-05-30 22:16:54,628] {logging_mixin.py:115} INFO - yellow_taxi_2022_04 /opt/***/output_2022-04.parquet 2022-04-02T06:00:00+00:00
[2022-05-30 22:16:54,705] {logging_mixin.py:115} INFO - connection established successfully, inserting data...
[2022-05-30 22:16:54,969] {taskinstance.py:1890} ERROR - Task failed with exception
Traceback (most recent call last):
  File "/home/airflow/.local/lib/python3.7/site-packages/airflow/operators/python.py", line 171, in execute
    return_value = self.execute_callable()
  File "/home/airflow/.local/lib/python3.7/site-packages/airflow/operators/python.py", line 189, in execute_callable
    return self.python_callable(*self.op_args, **self.op_kwargs)
  File "/opt/airflow/dags/ingest_script.py", line 18, in ingest_callable
    df_iter = pd.read_parquet(parquet_file)
  File "/home/airflow/.local/lib/python3.7/site-packages/pandas/io/parquet.py", line 500, in read_parquet
    **kwargs,
  File "/home/airflow/.local/lib/python3.7/site-packages/pandas/io/parquet.py", line 240, in read
    path_or_handle, columns=columns, **kwargs
  File "/home/airflow/.local/lib/python3.7/site-packages/pyarrow/parquet.py", line 1915, in read_table
    coerce_int96_timestamp_unit=coerce_int96_timestamp_unit
  File "/home/airflow/.local/lib/python3.7/site-packages/pyarrow/parquet.py", line 1711, in __init__
    [fragment], schema=fragment.physical_schema,
  File "pyarrow/_dataset.pyx", line 978, in pyarrow._dataset.Fragment.physical_schema.__get__
  File "pyarrow/error.pxi", line 143, in pyarrow.lib.pyarrow_internal_check_status
  File "pyarrow/error.pxi", line 99, in pyarrow.lib.check_status
pyarrow.lib.ArrowInvalid: Could not open Parquet input source '<Buffer>': Parquet magic bytes not found in footer. Either the file is corrupted or this is not a parquet file.
[2022-05-30 22:16:55,098] {taskinstance.py:1401} INFO - Marking task as FAILED. dag_id=LocalIngestionDag, task_id=ingest, execution_date=20220402T060000, start_date=20220530T221653, end_date=20220530T221655
[2022-05-30 22:16:55,207] {standard_task_runner.py:97} ERROR - Failed to execute job 216 for task ingest (Could not open Parquet input source '<Buffer>': Parquet magic bytes not found in footer. Either the file is corrupted or this is not a parquet file.; 1347)
[2022-05-30 22:16:55,477] {local_task_job.py:156} INFO - Task exited with return code 1
[2022-05-30 22:16:55,627] {local_task_job.py:273} INFO - 0 downstream tasks scheduled from follow-on schedule check
[2022-05-30 22:28:16,591] {taskinstance.py:1160} INFO - Dependencies all met for <TaskInstance: LocalIngestionDag.ingest scheduled__2022-04-02T06:00:00+00:00 [queued]>
[2022-05-30 22:28:16,640] {taskinstance.py:1160} INFO - Dependencies all met for <TaskInstance: LocalIngestionDag.ingest scheduled__2022-04-02T06:00:00+00:00 [queued]>
[2022-05-30 22:28:16,645] {taskinstance.py:1357} INFO - 
--------------------------------------------------------------------------------
[2022-05-30 22:28:16,647] {taskinstance.py:1358} INFO - Starting attempt 1 of 1
[2022-05-30 22:28:16,649] {taskinstance.py:1359} INFO - 
--------------------------------------------------------------------------------
[2022-05-30 22:28:16,758] {taskinstance.py:1378} INFO - Executing <Task(PythonOperator): ingest> on 2022-04-02 06:00:00+00:00
[2022-05-30 22:28:16,782] {standard_task_runner.py:52} INFO - Started process 2137 to run task
[2022-05-30 22:28:16,790] {standard_task_runner.py:79} INFO - Running: ['***', 'tasks', 'run', 'LocalIngestionDag', 'ingest', 'scheduled__2022-04-02T06:00:00+00:00', '--job-id', '265', '--raw', '--subdir', 'DAGS_FOLDER/data_ingestion_local.py', '--cfg-path', '/tmp/tmpvvle33u9', '--error-file', '/tmp/tmp_j8ve9bu']
[2022-05-30 22:28:16,794] {standard_task_runner.py:80} INFO - Job 265: Subtask ingest
[2022-05-30 22:28:16,896] {task_command.py:370} INFO - Running <TaskInstance: LocalIngestionDag.ingest scheduled__2022-04-02T06:00:00+00:00 [running]> on host 8ac972de2f4f
[2022-05-30 22:28:16,993] {warnings.py:110} WARNING - /home/***/.local/lib/python3.7/site-packages/***/utils/context.py:202: AirflowContextDeprecationWarning: Accessing 'execution_date' from the template is deprecated and will be removed in a future version. Please use 'data_interval_start' or 'logical_date' instead.
  warnings.warn(_create_deprecation_warning(key, self._deprecation_replacements[key]))

[2022-05-30 22:28:17,102] {taskinstance.py:1572} INFO - Exporting the following env vars:
AIRFLOW_CTX_DAG_OWNER=***
AIRFLOW_CTX_DAG_ID=LocalIngestionDag
AIRFLOW_CTX_TASK_ID=ingest
AIRFLOW_CTX_EXECUTION_DATE=2022-04-02T06:00:00+00:00
AIRFLOW_CTX_TRY_NUMBER=1
AIRFLOW_CTX_DAG_RUN_ID=scheduled__2022-04-02T06:00:00+00:00
[2022-05-30 22:28:17,122] {logging_mixin.py:115} INFO - yellow_taxi_2022_04 /opt/***/output_2022-04.parquet 2022-04-02T06:00:00+00:00
[2022-05-30 22:28:17,186] {logging_mixin.py:115} INFO - connection established successfully, inserting data...
[2022-05-30 22:28:17,271] {taskinstance.py:1890} ERROR - Task failed with exception
Traceback (most recent call last):
  File "/home/airflow/.local/lib/python3.7/site-packages/airflow/operators/python.py", line 171, in execute
    return_value = self.execute_callable()
  File "/home/airflow/.local/lib/python3.7/site-packages/airflow/operators/python.py", line 189, in execute_callable
    return self.python_callable(*self.op_args, **self.op_kwargs)
  File "/opt/airflow/dags/ingest_script.py", line 18, in ingest_callable
    df = pd.read_parquet(parquet_file)
  File "/home/airflow/.local/lib/python3.7/site-packages/pandas/io/parquet.py", line 500, in read_parquet
    **kwargs,
  File "/home/airflow/.local/lib/python3.7/site-packages/pandas/io/parquet.py", line 240, in read
    path_or_handle, columns=columns, **kwargs
  File "/home/airflow/.local/lib/python3.7/site-packages/pyarrow/parquet.py", line 1915, in read_table
    coerce_int96_timestamp_unit=coerce_int96_timestamp_unit
  File "/home/airflow/.local/lib/python3.7/site-packages/pyarrow/parquet.py", line 1711, in __init__
    [fragment], schema=fragment.physical_schema,
  File "pyarrow/_dataset.pyx", line 978, in pyarrow._dataset.Fragment.physical_schema.__get__
  File "pyarrow/error.pxi", line 143, in pyarrow.lib.pyarrow_internal_check_status
  File "pyarrow/error.pxi", line 99, in pyarrow.lib.check_status
pyarrow.lib.ArrowInvalid: Could not open Parquet input source '<Buffer>': Parquet magic bytes not found in footer. Either the file is corrupted or this is not a parquet file.
[2022-05-30 22:28:17,282] {taskinstance.py:1401} INFO - Marking task as FAILED. dag_id=LocalIngestionDag, task_id=ingest, execution_date=20220402T060000, start_date=20220530T222816, end_date=20220530T222817
[2022-05-30 22:28:17,295] {standard_task_runner.py:97} ERROR - Failed to execute job 265 for task ingest (Could not open Parquet input source '<Buffer>': Parquet magic bytes not found in footer. Either the file is corrupted or this is not a parquet file.; 2137)
[2022-05-30 22:28:17,355] {local_task_job.py:156} INFO - Task exited with return code 1
[2022-05-30 22:28:17,388] {local_task_job.py:273} INFO - 0 downstream tasks scheduled from follow-on schedule check
