[2022-05-30 18:13:00,686] {taskinstance.py:1160} INFO - Dependencies all met for <TaskInstance: data_ingestion_gcs_dag.local_to_gcs_task manual__2022-05-30T18:10:20.715614+00:00 [queued]>
[2022-05-30 18:13:00,706] {taskinstance.py:1160} INFO - Dependencies all met for <TaskInstance: data_ingestion_gcs_dag.local_to_gcs_task manual__2022-05-30T18:10:20.715614+00:00 [queued]>
[2022-05-30 18:13:00,708] {taskinstance.py:1357} INFO - 
--------------------------------------------------------------------------------
[2022-05-30 18:13:00,709] {taskinstance.py:1358} INFO - Starting attempt 1 of 2
[2022-05-30 18:13:00,711] {taskinstance.py:1359} INFO - 
--------------------------------------------------------------------------------
[2022-05-30 18:13:00,731] {taskinstance.py:1378} INFO - Executing <Task(PythonOperator): local_to_gcs_task> on 2022-05-30 18:10:20.715614+00:00
[2022-05-30 18:13:00,738] {standard_task_runner.py:52} INFO - Started process 2796 to run task
[2022-05-30 18:13:00,744] {standard_task_runner.py:79} INFO - Running: ['***', 'tasks', 'run', 'data_ingestion_gcs_dag', 'local_to_gcs_task', 'manual__2022-05-30T18:10:20.715614+00:00', '--job-id', '8', '--raw', '--subdir', 'DAGS_FOLDER/data_ingestion_gcs_dag.py', '--cfg-path', '/tmp/tmp17_51n86', '--error-file', '/tmp/tmp84j33sfw']
[2022-05-30 18:13:00,747] {standard_task_runner.py:80} INFO - Job 8: Subtask local_to_gcs_task
[2022-05-30 18:13:00,817] {task_command.py:370} INFO - Running <TaskInstance: data_ingestion_gcs_dag.local_to_gcs_task manual__2022-05-30T18:10:20.715614+00:00 [running]> on host e2389547c18a
[2022-05-30 18:13:00,875] {taskinstance.py:1572} INFO - Exporting the following env vars:
AIRFLOW_CTX_DAG_OWNER=***
AIRFLOW_CTX_DAG_ID=data_ingestion_gcs_dag
AIRFLOW_CTX_TASK_ID=local_to_gcs_task
AIRFLOW_CTX_EXECUTION_DATE=2022-05-30T18:10:20.715614+00:00
AIRFLOW_CTX_TRY_NUMBER=1
AIRFLOW_CTX_DAG_RUN_ID=manual__2022-05-30T18:10:20.715614+00:00
[2022-05-30 18:13:03,888] {_metadata.py:104} WARNING - Compute Engine Metadata server unavailable on attempt 1 of 3. Reason: timed out
[2022-05-30 18:13:03,902] {_metadata.py:104} WARNING - Compute Engine Metadata server unavailable on attempt 2 of 3. Reason: [Errno 111] Connection refused
[2022-05-30 18:13:03,904] {_metadata.py:104} WARNING - Compute Engine Metadata server unavailable on attempt 3 of 3. Reason: [Errno 111] Connection refused
[2022-05-30 18:13:03,906] {_default.py:284} WARNING - Authentication failed using Compute Engine authentication due to unavailable metadata server.
[2022-05-30 18:13:03,908] {taskinstance.py:1890} ERROR - Task failed with exception
Traceback (most recent call last):
  File "/home/airflow/.local/lib/python3.7/site-packages/airflow/operators/python.py", line 171, in execute
    return_value = self.execute_callable()
  File "/home/airflow/.local/lib/python3.7/site-packages/airflow/operators/python.py", line 189, in execute_callable
    return self.python_callable(*self.op_args, **self.op_kwargs)
  File "/opt/airflow/dags/data_ingestion_gcs_dag.py", line 47, in upload_to_gcs
    client = storage.Client()
  File "/home/airflow/.local/lib/python3.7/site-packages/google/cloud/storage/client.py", line 128, in __init__
    _http=_http,
  File "/home/airflow/.local/lib/python3.7/site-packages/google/cloud/client/__init__.py", line 320, in __init__
    _ClientProjectMixin.__init__(self, project=project, credentials=credentials)
  File "/home/airflow/.local/lib/python3.7/site-packages/google/cloud/client/__init__.py", line 268, in __init__
    project = self._determine_default(project)
  File "/home/airflow/.local/lib/python3.7/site-packages/google/cloud/client/__init__.py", line 287, in _determine_default
    return _determine_default_project(project)
  File "/home/airflow/.local/lib/python3.7/site-packages/google/cloud/_helpers/__init__.py", line 152, in _determine_default_project
    _, project = google.auth.default()
  File "/home/airflow/.local/lib/python3.7/site-packages/google/auth/_default.py", line 579, in default
    raise exceptions.DefaultCredentialsError(_HELP_MESSAGE)
google.auth.exceptions.DefaultCredentialsError: Could not automatically determine credentials. Please set GOOGLE_APPLICATION_CREDENTIALS or explicitly create credentials and re-run the application. For more information, please see https://cloud.google.com/docs/authentication/getting-started
[2022-05-30 18:13:03,956] {taskinstance.py:1401} INFO - Marking task as UP_FOR_RETRY. dag_id=data_ingestion_gcs_dag, task_id=local_to_gcs_task, execution_date=20220530T181020, start_date=20220530T181300, end_date=20220530T181303
[2022-05-30 18:13:03,985] {standard_task_runner.py:97} ERROR - Failed to execute job 8 for task local_to_gcs_task (Could not automatically determine credentials. Please set GOOGLE_APPLICATION_CREDENTIALS or explicitly create credentials and re-run the application. For more information, please see https://cloud.google.com/docs/authentication/getting-started; 2796)
[2022-05-30 18:13:04,036] {local_task_job.py:156} INFO - Task exited with return code 1
[2022-05-30 18:13:04,148] {local_task_job.py:273} INFO - 0 downstream tasks scheduled from follow-on schedule check
